
<mujoco>
    <compiler angle="radian" meshdir="REU_Snake/Mesh/" />
  <asset>
    <mesh name="ReU_mesh" file="ReU_Mesh.STL" scale="0.0254 0.0254 0.0254"/>
    <material name="red" rgba="1 0 0 1"/>
    <material name="blue" rgba="0 0 1 1"/>
    <material name="green_dark" rgba="0 0.6 0 1"/>  
    <material name="green_light" rgba="0 0.4 0 1"/>
    <material name="debug_col" rgba="1 0.5 0.5 0.3"/> 
  </asset>
  
  <worldbody>
  <light pos="0 0 1.5" dir="0 0 -1" directional="true"/>
    

        <body name="mod_0_in" pos="-0.0254 -0.0 0.01">
        <joint name="mod_0_free" type="free"/>   
        
        


        <body name="mod_0_body" pos="0 0 0">
        <geom name = "mesh0" type="mesh" mesh="ReU_mesh" pos = "0 0 0" material="green_dark" contype="2" conaffinity="1" group="0"/>

        
        <body name="mod_0_out" pos="0 0 0" euler="0 0 0 ">
                <inertial pos="0 0 0" mass="0.1" diaginertia="0.001 0.001 0.001"/>
                


  
        <body name="mod_1_in" pos="0.053085999999999994 0.000254 0.051053999999999995" euler="0 0 1.57079632679">
       
        
  
        <joint name="joint_1" type="hinge" pos="0.0254 0.018796 0.01651" axis="0 1 0" range="-1.57079632679 1.57079632679" 
                limited="true" damping="3.18" frictionloss="0.2"/>


        <body name="mod_1_body" pos="0 0 0">
        <geom name = "mesh1" type="mesh" mesh="ReU_mesh" pos = "0 0 0" material="green_dark" contype="2" conaffinity="1" group="0"/>

        
        <body name="mod_1_out" pos="0 0 0" euler="0 0 0 ">
                <inertial pos="0 0 0" mass="0.1" diaginertia="0.001 0.001 0.001"/>
                <geom name = "mod_1_out" type="cylinder" size="0.001 0.001" pos="0.011921999999999999 0.025654 0.06858" euler="0 1.57079632679 0 " material="debug_col" 
                contype="2" conaffinity="1" group="0"/>
    
        
  
        <body name="mod_2_in" pos="0.053085999999999994 0.000254 0.051053999999999995" euler="0 0 1.57079632679">
       
        
  
        <joint name="joint_2" type="hinge" pos="0.0254 0.018796 0.01651" axis="0 1 0" range="-1.57079632679 1.57079632679" 
                limited="true" damping="3.18" frictionloss="0.2"/>


        <body name="mod_2_body" pos="0 0 0">
        <geom name = "mesh2" type="mesh" mesh="ReU_mesh" pos = "0 0 0" material="green_dark" contype="2" conaffinity="1" group="0"/>

        
        <body name="mod_2_out" pos="0 0 0" euler="0 0 0 ">
                <inertial pos="0 0 0" mass="0.1" diaginertia="0.001 0.001 0.001"/>
                <geom name = "mod_2_out" type="cylinder" size="0.001 0.001" pos="0.011921999999999999 0.025654 0.06858" euler="0 1.57079632679 0 " material="debug_col" 
                contype="2" conaffinity="1" group="0"/>
    
        
  
        <body name="mod_3_in" pos="0.053085999999999994 0.000254 0.051053999999999995" euler="0 0 1.57079632679">
       
        
  
        <joint name="joint_3" type="hinge" pos="0.0254 0.018796 0.01651" axis="0 1 0" range="-1.57079632679 1.57079632679" 
                limited="true" damping="3.18" frictionloss="0.2"/>


        <body name="mod_3_body" pos="0 0 0">
        <geom name = "mesh3" type="mesh" mesh="ReU_mesh" pos = "0 0 0" material="green_dark" contype="2" conaffinity="1" group="0"/>

        
        <body name="mod_3_out" pos="0 0 0" euler="0 0 0 ">
                <inertial pos="0 0 0" mass="0.1" diaginertia="0.001 0.001 0.001"/>
                <geom name = "mod_3_out" type="cylinder" size="0.001 0.001" pos="0.011921999999999999 0.025654 0.06858" euler="0 1.57079632679 0 " material="debug_col" 
                contype="2" conaffinity="1" group="0"/>
    
        
<body name="mod_4_in" pos="0.053085999999999994 0.000254 0.051053999999999995" euler="0 0 1.57079632679">
       
<inertial pos="0 0 0" mass="0.1" diaginertia="0.001 0.001 0.001"/>
        <joint name="joint_4" type="hinge" pos="0.0254 0.018796 0.01651" axis="0 0 1" range="-1.57079632679 1.57079632679" 
                limited="true" damping="3.18" frictionloss="0.2"/>
                </body>
 
    
    </body> </body> </body>
    
    
    </body> </body> </body>
    
    
    </body> </body> </body>
    
    
    </body> </body> </body>
    


</worldbody>


<actuator>


      <position name="servo_1_pos" joint="joint_1" kp="10" ctrlrange="-1.5708 1.5708" ctrllimited="true" forcerange="-10.0 10.0" forcelimited="true"/>
      
      <motor name="servo_2_pos" joint="joint_2" ctrlrange="-10.0 10.0" ctrllimited="true"/>

      
      <position name="servo_3_pos" joint="joint_3" kp="10" ctrlrange="-1.5708 1.5708" ctrllimited="true" forcerange="-10.0 10.0" forcelimited="true"/>
      
      <motor name="servo_4_pos" joint="joint_2" ctrlrange="-10.0 10.0" ctrllimited="true"/>

      

</actuator>

<sensor>
    <jointactuatorfrc joint="joint_1" name="joint_1_torque_sensor"/>
    <jointactuatorfrc joint="joint_2" name="joint_2_torque_sensor"/>
    <jointactuatorfrc joint="joint_3" name="joint_3_torque_sensor"/></sensor>

</mujoco>

